<?xml version="1.0" encoding="UTF-8"?>
<!-- Generated by org.testng.reporters.JUnitXMLReporter -->
<testsuite ignored="0" hostname="LAPTOP-J49DONU2" failures="2" tests="4" name="Default test" time="5.155" errors="0" timestamp="2022-05-02T18:33:10 GET">
  <testcase classname="Scenario2" name="AddUser" time="4.041"/>
  <testcase classname="Scenario2" name="AlreadyAuthorized" time="0.389">
    <failure type="java.lang.AssertionError" message="expected:&amp;lt;io.restassured.internal.RestAssuredResponseImpl@57f9b467&amp;gt; but was:&amp;lt;true&amp;gt;">
      <![CDATA[java.lang.AssertionError: expected:<io.restassured.internal.RestAssuredResponseImpl@57f9b467> but was:<true>
at org.junit.Assert.fail(Assert.java:89)
at org.junit.Assert.failNotEquals(Assert.java:835)
at org.junit.Assert.assertEquals(Assert.java:120)
at org.junit.Assert.assertEquals(Assert.java:146)
at Scenario2.AlreadyAuthorized(Scenario2.java:63)
at java.base/jdk.internal.reflect.NativeMethodAccessorImpl.invoke0(Native Method)
at java.base/jdk.internal.reflect.NativeMethodAccessorImpl.invoke(NativeMethodAccessorImpl.java:77)
at java.base/jdk.internal.reflect.DelegatingMethodAccessorImpl.invoke(DelegatingMethodAccessorImpl.java:43)
at java.base/java.lang.reflect.Method.invoke(Method.java:568)
at org.testng.internal.invokers.MethodInvocationHelper.invokeMethod(MethodInvocationHelper.java:135)
at org.testng.internal.invokers.TestInvoker.invokeMethod(TestInvoker.java:673)
at org.testng.internal.invokers.TestInvoker.invokeTestMethod(TestInvoker.java:220)
at org.testng.internal.invokers.MethodRunner.runInSequence(MethodRunner.java:50)
at org.testng.internal.invokers.TestInvoker$MethodInvocationAgent.invoke(TestInvoker.java:945)
at org.testng.internal.invokers.TestInvoker.invokeTestMethods(TestInvoker.java:193)
at org.testng.internal.invokers.TestMethodWorker.invokeTestMethods(TestMethodWorker.java:146)
at org.testng.internal.invokers.TestMethodWorker.run(TestMethodWorker.java:128)
at java.base/java.util.ArrayList.forEach(ArrayList.java:1511)
at org.testng.TestRunner.privateRun(TestRunner.java:808)
at org.testng.TestRunner.run(TestRunner.java:603)
at org.testng.SuiteRunner.runTest(SuiteRunner.java:429)
at org.testng.SuiteRunner.runSequentially(SuiteRunner.java:423)
at org.testng.SuiteRunner.privateRun(SuiteRunner.java:383)
at org.testng.SuiteRunner.run(SuiteRunner.java:326)
at org.testng.SuiteRunnerWorker.runSuite(SuiteRunnerWorker.java:52)
at org.testng.SuiteRunnerWorker.run(SuiteRunnerWorker.java:95)
at org.testng.TestNG.runSuitesSequentially(TestNG.java:1249)
at org.testng.TestNG.runSuitesLocally(TestNG.java:1169)
at org.testng.TestNG.runSuites(TestNG.java:1092)
at org.testng.TestNG.run(TestNG.java:1060)
at org.testng.remote.AbstractRemoteTestNG.run(AbstractRemoteTestNG.java:115)
at org.testng.remote.RemoteTestNG.initAndRun(RemoteTestNG.java:251)
at org.testng.remote.RemoteTestNG.main(RemoteTestNG.java:77)
]]>
    </failure>
  </testcase> <!-- AlreadyAuthorized -->
  <testcase classname="Scenario2" name="GenerateToken" time="0.321"/>
  <testcase classname="Scenario2" name="NotAuthorized" time="0.318">
    <failure type="java.lang.AssertionError" message="expected:&amp;lt;io.restassured.internal.RestAssuredResponseImpl@1df1ced0&amp;gt; but was:&amp;lt;false&amp;gt;">
      <![CDATA[java.lang.AssertionError: expected:<io.restassured.internal.RestAssuredResponseImpl@1df1ced0> but was:<false>
at org.junit.Assert.fail(Assert.java:89)
at org.junit.Assert.failNotEquals(Assert.java:835)
at org.junit.Assert.assertEquals(Assert.java:120)
at org.junit.Assert.assertEquals(Assert.java:146)
at Scenario2.NotAuthorized(Scenario2.java:35)
at java.base/jdk.internal.reflect.NativeMethodAccessorImpl.invoke0(Native Method)
at java.base/jdk.internal.reflect.NativeMethodAccessorImpl.invoke(NativeMethodAccessorImpl.java:77)
at java.base/jdk.internal.reflect.DelegatingMethodAccessorImpl.invoke(DelegatingMethodAccessorImpl.java:43)
at java.base/java.lang.reflect.Method.invoke(Method.java:568)
at org.testng.internal.invokers.MethodInvocationHelper.invokeMethod(MethodInvocationHelper.java:135)
at org.testng.internal.invokers.TestInvoker.invokeMethod(TestInvoker.java:673)
at org.testng.internal.invokers.TestInvoker.invokeTestMethod(TestInvoker.java:220)
at org.testng.internal.invokers.MethodRunner.runInSequence(MethodRunner.java:50)
at org.testng.internal.invokers.TestInvoker$MethodInvocationAgent.invoke(TestInvoker.java:945)
at org.testng.internal.invokers.TestInvoker.invokeTestMethods(TestInvoker.java:193)
at org.testng.internal.invokers.TestMethodWorker.invokeTestMethods(TestMethodWorker.java:146)
at org.testng.internal.invokers.TestMethodWorker.run(TestMethodWorker.java:128)
at java.base/java.util.ArrayList.forEach(ArrayList.java:1511)
at org.testng.TestRunner.privateRun(TestRunner.java:808)
at org.testng.TestRunner.run(TestRunner.java:603)
at org.testng.SuiteRunner.runTest(SuiteRunner.java:429)
at org.testng.SuiteRunner.runSequentially(SuiteRunner.java:423)
at org.testng.SuiteRunner.privateRun(SuiteRunner.java:383)
at org.testng.SuiteRunner.run(SuiteRunner.java:326)
at org.testng.SuiteRunnerWorker.runSuite(SuiteRunnerWorker.java:52)
at org.testng.SuiteRunnerWorker.run(SuiteRunnerWorker.java:95)
at org.testng.TestNG.runSuitesSequentially(TestNG.java:1249)
at org.testng.TestNG.runSuitesLocally(TestNG.java:1169)
at org.testng.TestNG.runSuites(TestNG.java:1092)
at org.testng.TestNG.run(TestNG.java:1060)
at org.testng.remote.AbstractRemoteTestNG.run(AbstractRemoteTestNG.java:115)
at org.testng.remote.RemoteTestNG.initAndRun(RemoteTestNG.java:251)
at org.testng.remote.RemoteTestNG.main(RemoteTestNG.java:77)
]]>
    </failure>
  </testcase> <!-- NotAuthorized -->
</testsuite> <!-- Default test -->
